<sdf version='1.7'>
  <model name='WAM-V'>
    <link name='wamv/base_link'>
      <inertial>
        <pose>-0.005402 -0 0.252116 0 -0 0</pose>
        <mass>249.382</mass>
        <inertia>
          <ixx>224.43</ixx>
          <ixy>1.91919e-17</ixy>
          <ixz>1.41652</ixz>
          <iyy>453.226</iyy>
          <iyz>-8.95695e-16</iyz>
          <izz>499.347</izz>
        </inertia>
      </inertial>
      <collision name='wamv/base_link_fixed_joint_lump__front_camera_post_collision_collision'>
        <pose>0.7 0 1.55975 0 -0 0</pose>
        <geometry>
          <cylinder>
            <length>0.5265</length>
            <radius>0.0076</radius>
          </cylinder>
        </geometry>
      </collision>
      <collision name='wamv/base_link_fixed_joint_lump__front_camera_post_arm_collision_collision_1'>
        <pose>0.73 0 1.823 -1.20428 0 -1.5708</pose>
        <geometry>
          <cylinder>
            <length>0.065</length>
            <radius>0.008</radius>
          </cylinder>
        </geometry>
      </collision>
      <collision name='wamv/base_link_fixed_joint_lump__front_camera_lens_collision_collision_2'>
        <pose>0.767387 0 1.84534 3.14159 1.309 3.14159</pose>
        <geometry>
          <cylinder>
            <length>0.042</length>
            <radius>0.015</radius>
          </cylinder>
        </geometry>
      </collision>
      <collision name='wamv/base_link_fixed_joint_lump__front_camera_box_collision_collision_3'>
        <pose>0.730199 0 1.85531 0 0.261799 0</pose>
        <geometry>
          <box>
            <size>0.036 0.03 0.03</size>
          </box>
        </geometry>
      </collision>
      <collision name='wamv/base_link_fixed_joint_lump__lidar_wamv_post_collision_collision_4'>
        <pose>0.63 0 1.52325 0 -0 0</pose>
        <geometry>
          <cylinder>
            <length>0.4535</length>
            <radius>0.0076</radius>
          </cylinder>
        </geometry>
      </collision>
      <collision name='wamv/base_link_fixed_joint_lump__lidar_wamv_post_arm_collision_collision_5'>
        <pose>0.66 0 1.75 -1.20428 0 -1.5708</pose>
        <geometry>
          <cylinder>
            <length>0.065</length>
            <radius>0.008</radius>
          </cylinder>
        </geometry>
      </collision>
      <collision name='wamv/base_link_fixed_joint_lump__lidar_wamv_collision_collision_6'>
        <pose>0.7 0 1.8 0 0.139626 0</pose>
        <geometry>
          <cylinder>
            <length>0.075</length>
            <radius>0.055</radius>
          </cylinder>
        </geometry>
      </collision>
      <collision name='wamv/base_link_fixed_joint_lump__cpu_case_1_collision_collision_7'>
        <pose>0.035 0 1.53 0 -0 0</pose>
        <geometry>
          <box>
            <size>0.595 0.83 0.47</size>
          </box>
        </geometry>
      </collision>
      <collision name='wamv/base_link_fixed_joint_lump__cpu_case_2_collision_collision_8'>
        <pose>-0.45 0 1.438 0 -0 0</pose>
        <geometry>
          <box>
            <size>0.375 0.64 0.28</size>
          </box>
        </geometry>
      </collision>
      <collision name='wamv/base_link_fixed_joint_lump__left_float_collision_9'>
        <pose>-0.4 1.03 0.2 0 1.5708 0</pose>
        <geometry>
          <cylinder>
            <length>4</length>
            <radius>0.2</radius>
          </cylinder>
        </geometry>
      </collision>
      <collision name='wamv/base_link_fixed_joint_lump__left_mid_float_collision_10'>
        <pose>1.85 1.03 0.3 0 1.38 0</pose>
        <geometry>
          <cylinder>
            <length>0.5</length>
            <radius>0.17</radius>
          </cylinder>
        </geometry>
      </collision>
      <collision name='wamv/base_link_fixed_joint_lump__left_front_float_collision_11'>
        <pose>2.3 1.03 0.4 0 1.3 0</pose>
        <geometry>
          <cylinder>
            <length>0.45</length>
            <radius>0.12</radius>
          </cylinder>
        </geometry>
      </collision>
      <collision name='wamv/base_link_fixed_joint_lump__front_left_beam_lower_collision_12'>
        <pose>0.9 0.85 1 0.78 -0 0</pose>
        <geometry>
          <cylinder>
            <length>0.5</length>
            <radius>0.04</radius>
          </cylinder>
        </geometry>
      </collision>
      <collision name='wamv/base_link_fixed_joint_lump__front_left_beam_upper_collision_13'>
        <pose>0.9 0.6 1.18 1.35 -0 0</pose>
        <geometry>
          <cylinder>
            <length>0.2</length>
            <radius>0.04</radius>
          </cylinder>
        </geometry>
      </collision>
      <collision name='wamv/base_link_fixed_joint_lump__mid_left_beam_lower_collision_14'>
        <pose>-0.65 0.99 0.7 0.1 0.25 0</pose>
        <geometry>
          <cylinder>
            <length>0.45</length>
            <radius>0.03</radius>
          </cylinder>
        </geometry>
      </collision>
      <collision name='wamv/base_link_fixed_joint_lump__mid_left_beam_medium_collision_15'>
        <pose>-0.57 0.87 1.05 0.75 0.25 0</pose>
        <geometry>
          <cylinder>
            <length>0.32</length>
            <radius>0.03</radius>
          </cylinder>
        </geometry>
      </collision>
      <collision name='wamv/base_link_fixed_joint_lump__mid_left_beam_upper_collision_16'>
        <pose>-0.55 0.65 1.17 1.35 0.25 0</pose>
        <geometry>
          <cylinder>
            <length>0.3</length>
            <radius>0.03</radius>
          </cylinder>
        </geometry>
      </collision>
      <collision name='wamv/base_link_fixed_joint_lump__rear_left_beam_lower_collision_17'>
        <pose>-0.74 1.03 0.7 0 -0.15 0</pose>
        <geometry>
          <cylinder>
            <length>0.45</length>
            <radius>0.03</radius>
          </cylinder>
        </geometry>
      </collision>
      <collision name='wamv/base_link_fixed_joint_lump__rear_left_beam_medium_collision_18'>
        <pose>-0.79 0.91 1.05 0.75 -0.15 -0</pose>
        <geometry>
          <cylinder>
            <length>0.32</length>
            <radius>0.03</radius>
          </cylinder>
        </geometry>
      </collision>
      <collision name='wamv/base_link_fixed_joint_lump__rear_left_beam_upper_collision_19'>
        <pose>-0.81 0.67 1.18 1.45 -0.15 0</pose>
        <geometry>
          <cylinder>
            <length>0.3</length>
            <radius>0.03</radius>
          </cylinder>
        </geometry>
      </collision>
      <collision name='wamv/base_link_fixed_joint_lump__left_joint_collision_20'>
        <pose>0.58 1.03 0.6 0 -0.6 0</pose>
        <geometry>
          <box>
            <size>0.65 0.2 0.1</size>
          </box>
        </geometry>
      </collision>
      <collision name='wamv/base_link_fixed_joint_lump__right_float_collision_21'>
        <pose>-0.4 -1.03 0.2 0 1.5708 0</pose>
        <geometry>
          <cylinder>
            <length>4</length>
            <radius>0.2</radius>
          </cylinder>
        </geometry>
      </collision>
      <collision name='wamv/base_link_fixed_joint_lump__right_mid_float_collision_22'>
        <pose>1.85 -1.03 0.3 0 1.38 0</pose>
        <geometry>
          <cylinder>
            <length>0.5</length>
            <radius>0.17</radius>
          </cylinder>
        </geometry>
      </collision>
      <collision name='wamv/base_link_fixed_joint_lump__right_front_float_collision_23'>
        <pose>2.3 -1.03 0.4 0 1.3 0</pose>
        <geometry>
          <cylinder>
            <length>0.45</length>
            <radius>0.12</radius>
          </cylinder>
        </geometry>
      </collision>
      <collision name='wamv/base_link_fixed_joint_lump__front_right_beam_lower_collision_24'>
        <pose>0.9 -0.85 1 -0.78 0 0</pose>
        <geometry>
          <cylinder>
            <length>0.5</length>
            <radius>0.04</radius>
          </cylinder>
        </geometry>
      </collision>
      <collision name='wamv/base_link_fixed_joint_lump__front_right_beam_upper_collision_25'>
        <pose>0.9 -0.6 1.18 -1.35 0 0</pose>
        <geometry>
          <cylinder>
            <length>0.2</length>
            <radius>0.04</radius>
          </cylinder>
        </geometry>
      </collision>
      <collision name='wamv/base_link_fixed_joint_lump__mid_right_beam_lower_collision_26'>
        <pose>-0.65 -0.99 0.7 -0.1 0.25 0</pose>
        <geometry>
          <cylinder>
            <length>0.45</length>
            <radius>0.03</radius>
          </cylinder>
        </geometry>
      </collision>
      <collision name='wamv/base_link_fixed_joint_lump__mid_right_beam_medium_collision_27'>
        <pose>-0.57 -0.87 1.05 -0.75 0.25 0</pose>
        <geometry>
          <cylinder>
            <length>0.32</length>
            <radius>0.03</radius>
          </cylinder>
        </geometry>
      </collision>
      <collision name='wamv/base_link_fixed_joint_lump__mid_right_beam_upper_collision_28'>
        <pose>-0.55 -0.65 1.17 -1.35 0.25 0</pose>
        <geometry>
          <cylinder>
            <length>0.3</length>
            <radius>0.03</radius>
          </cylinder>
        </geometry>
      </collision>
      <collision name='wamv/base_link_fixed_joint_lump__rear_right_beam_lower_collision_29'>
        <pose>-0.74 -1.03 0.7 0 -0.15 0</pose>
        <geometry>
          <cylinder>
            <length>0.45</length>
            <radius>0.03</radius>
          </cylinder>
        </geometry>
      </collision>
      <collision name='wamv/base_link_fixed_joint_lump__rear_right_beam_medium_collision_30'>
        <pose>-0.79 -0.91 1.05 -0.75 -0.15 0</pose>
        <geometry>
          <cylinder>
            <length>0.32</length>
            <radius>0.03</radius>
          </cylinder>
        </geometry>
      </collision>
      <collision name='wamv/base_link_fixed_joint_lump__rear_right_beam_upper_collision_31'>
        <pose>-0.81 -0.67 1.18 -1.45 -0.15 0</pose>
        <geometry>
          <cylinder>
            <length>0.3</length>
            <radius>0.03</radius>
          </cylinder>
        </geometry>
      </collision>
      <collision name='wamv/base_link_fixed_joint_lump__right_joint_collision_32'>
        <pose>0.58 -1.03 0.6 0 -0.6 0</pose>
        <geometry>
          <box>
            <size>0.65 0.2 0.1</size>
          </box>
        </geometry>
      </collision>
      <collision name='wamv/base_link_fixed_joint_lump__top_base_collision_33'>
        <pose>0 0 1.25 0 -0 0</pose>
        <geometry>
          <box>
            <size>1.85 1 0.1</size>
          </box>
        </geometry>
      </collision>
      <collision name='wamv/base_link_fixed_joint_lump__left_battery_collision_collision_34'>
        <pose>0 1 0.6 0 -0 0</pose>
        <geometry>
          <box>
            <size>0.6 0.4 0.31</size>
          </box>
        </geometry>
      </collision>
      <collision name='wamv/base_link_fixed_joint_lump__right_battery_collision_collision_35'>
        <pose>0 -1 0.6 0 -0 0</pose>
        <geometry>
          <box>
            <size>0.6 0.4 0.31</size>
          </box>
        </geometry>
      </collision>
      <visual name='wamv/base_link_fixed_joint_lump__wamv/front_camera_post_link_visual'>
        <pose>0.7 0 1.55975 0 -0 0</pose>
        <geometry>
          <cylinder>
            <length>0.5265</length>
            <radius>0.0076</radius>
          </cylinder>
        </geometry>
        <material>
          <script>
            <name>Gazebo/Black</name>
            <uri>file://media/materials/scripts/gazebo.material</uri>
          </script>
        </material>
      </visual>
      <visual name='wamv/base_link_fixed_joint_lump__front_camera_post_arm_visual_visual_1'>
        <pose>0.692 0 1.82 -1.0472 0 -1.5708</pose>
        <geometry>
          <mesh>
            <scale>1 1 1</scale>
            <uri>model://vrx_gazebo/models/sensor_post/mesh/sensor_post_arm.dae</uri>
          </mesh>
        </geometry>
      </visual>
      <visual name='wamv/base_link_fixed_joint_lump__front_camera_visual_visual_2'>
        <pose>0.718124 0 1.85854 0.261799 0 1.5708</pose>
        <geometry>
          <mesh>
            <scale>1 1 1</scale>
            <uri>model://vrx_gazebo/models/mono_camera/mesh/mono_camera.dae</uri>
          </mesh>
        </geometry>
      </visual>
      <visual name='wamv/base_link_fixed_joint_lump__wamv/lidar_wamv_post_link_visual_3'>
        <pose>0.63 0 1.52325 0 -0 0</pose>
        <geometry>
          <cylinder>
            <length>0.4535</length>
            <radius>0.0076</radius>
          </cylinder>
        </geometry>
        <material>
          <script>
            <name>Gazebo/Black</name>
            <uri>file://media/materials/scripts/gazebo.material</uri>
          </script>
        </material>
      </visual>
      <visual name='wamv/base_link_fixed_joint_lump__lidar_wamv_post_arm_visual_visual_4'>
        <pose>0.622 0 1.747 -1.0472 0 -1.5708</pose>
        <geometry>
          <mesh>
            <scale>1 1 1</scale>
            <uri>model://vrx_gazebo/models/sensor_post/mesh/sensor_post_arm.dae</uri>
          </mesh>
        </geometry>
      </visual>
      <visual name='wamv/base_link_fixed_joint_lump__lidar_wamv_visual_visual_5'>
        <pose>0.695129 0 1.76534 0 0.139626 0</pose>
        <geometry>
          <mesh>
            <scale>1 1 1</scale>
            <uri>model://vrx_gazebo/models/3d_lidar/mesh/3d_lidar.dae</uri>
          </mesh>
        </geometry>
      </visual>
      <visual name='wamv/base_link_fixed_joint_lump__cpu_cases_visual_visual_6'>
        <pose>-0.077 0 0 0 -0 0</pose>
        <geometry>
          <mesh>
            <scale>1 1 1</scale>
            <uri>model://vrx_gazebo/models/cpu_cases/mesh/cpu_cases.dae</uri>
          </mesh>
        </geometry>
      </visual>
      <visual name='wamv/base_link_fixed_joint_lump__wamv/dummy_link_visual_7'>
        <pose>0 0 0 0 -0 0</pose>
        <geometry>
          <mesh>
            <scale>1 1 1</scale>
            <uri>model://wamv_description/models/WAM-V-Base/mesh/WAM-V-Base.dae</uri>
          </mesh>
        </geometry>
      </visual>
      <visual name='wamv/base_link_fixed_joint_lump__left_battery_visual_visual_8'>
        <pose>0 -0.03 0 0 -0 0</pose>
        <geometry>
          <mesh>
            <scale>1 1 1</scale>
            <uri>model://vrx_gazebo/models/battery/mesh/battery.dae</uri>
          </mesh>
        </geometry>
      </visual>
      <visual name='wamv/base_link_fixed_joint_lump__right_battery_visual_visual_9'>
        <pose>0 -2.03 0 0 -0 0</pose>
        <geometry>
          <mesh>
            <scale>1 1 1</scale>
            <uri>model://vrx_gazebo/models/battery/mesh/battery.dae</uri>
          </mesh>
        </geometry>
      </visual>
      <sensor name='front_camera_sensor' type='camera'>
        <update_rate>30</update_rate>
        <camera name='front_camera_camera'>
          <horizontal_fov>1.39626</horizontal_fov>
          <image>
            <width>1280</width>
            <height>720</height>
            <format>R8G8B8</format>
          </image>
          <clip>
            <near>0.05</near>
            <far>300</far>
          </clip>
          <noise>
            <type>gaussian</type>
            <mean>0</mean>
            <stddev>0.007</stddev>
          </noise>
        </camera>
        <plugin name='camera_plugin_front_camera' filename='libgazebo_ros_camera.so'>
          <alwaysOn>1</alwaysOn>
          <updateRate>0.0</updateRate>
          <cameraName>wamv/sensors/cameras/front_camera</cameraName>
          <imageTopicName>image_raw</imageTopicName>
          <cameraInfoTopicName>camera_info</cameraInfoTopicName>
          <frameName>wamv/front_camera_link_optical</frameName>
          <hackBaseline>0.07</hackBaseline>
          <distortionK1>0.0</distortionK1>
          <distortionK2>0.0</distortionK2>
          <distortionK3>0.0</distortionK3>
          <distortionT1>0.0</distortionT1>
          <distortionT2>0.0</distortionT2>
        </plugin>
        <pose>0.75 0 1.85 0 0.261799 0</pose>
      </sensor>
      <sensor name='lidar_wamv_sensor' type='gpu_ray'>
        <update_rate>10</update_rate>
        <ray>
          <scan>
            <horizontal>
              <samples>18750</samples>
              <resolution>0.1</resolution>
              <min_angle>-3.14159</min_angle>
              <max_angle>3.14159</max_angle>
            </horizontal>
            <vertical>
              <samples>16</samples>
              <resolution>1</resolution>
              <min_angle>-0.261799</min_angle>
              <max_angle>0.261799</max_angle>
            </vertical>
          </scan>
          <range>
            <min>0.1</min>
            <max>130</max>
          </range>
          <noise>
            <type>gaussian</type>
            <mean>0</mean>
            <stddev>0.01</stddev>
          </noise>
        </ray>
        <plugin name='lidar_wamv_plugin' filename='libgazebo_ros_velodyne_gpu_laser.so'>
          <topicName>wamv/sensors/lidars/lidar_wamv/points</topicName>
          <frameName>wamv/lidar_wamv_link</frameName>
          <min_intensity>0</min_intensity>
        </plugin>
        <pose>0.7 0 1.8 0 0.139626 0</pose>
      </sensor>
    </link>
    <joint name='wamv/front_left_chasis_engine_joint' type='revolute'>
      <pose relative_to='wamv/base_link'>1.75 1.02713 0.318237 0 0 -1.5708</pose>
      <parent>wamv/base_link</parent>
      <child>wamv/front_left_engine_link</child>
      <axis>
        <xyz>0 0 1</xyz>
        <limit>
          <lower>-3.14159</lower>
          <upper>3.14159</upper>
          <effort>10</effort>
          <velocity>10</velocity>
        </limit>
        <dynamics>
          <spring_reference>0</spring_reference>
          <spring_stiffness>0</spring_stiffness>
        </dynamics>
      </axis>
    </joint>
    <link name='wamv/front_left_engine_link'>
      <pose relative_to='wamv/front_left_chasis_engine_joint'>0 0 0 0 -0 0</pose>
      <inertial>
        <pose>0 0 0 0 -0 0</pose>
        <mass>15</mass>
        <inertia>
          <ixx>0.889245</ixx>
          <ixy>0</ixy>
          <ixz>0</ixz>
          <iyy>0.911125</iyy>
          <iyz>0</iyz>
          <izz>0.078125</izz>
        </inertia>
      </inertial>
      <collision name='wamv/front_left_engine_link_fixed_joint_lump__front_left_engine_vertical_axis_collision_collision'>
        <pose>-0.16 0 -0.24 0 -0 0</pose>
        <geometry>
          <box>
            <size>0.2 0.15 0.83</size>
          </box>
        </geometry>
      </collision>
      <collision name='wamv/front_left_engine_link_fixed_joint_lump__front_left_engine_rear_end_collision_collision_1'>
        <pose>-0.34 0 0.12 0 -0 0</pose>
        <geometry>
          <box>
            <size>0.12 0.15 0.12</size>
          </box>
        </geometry>
      </collision>
      <visual name='wamv/front_left_engine_link_visual'>
        <pose>0 0 0 0 -0 0</pose>
        <geometry>
          <mesh>
            <scale>1 1 1</scale>
            <uri>model://wamv_description/models/engine/mesh/engine.dae</uri>
          </mesh>
        </geometry>
      </visual>
    </link>
    <joint name='wamv/front_left_engine_propeller_joint' type='revolute'>
      <pose relative_to='wamv/front_left_engine_link'>-0.278156 0 -0.509371 0 -0 0</pose>
      <parent>wamv/front_left_engine_link</parent>
      <child>wamv/front_left_propeller_link</child>
      <axis>
        <xyz>1 0 0</xyz>
        <limit>
          <effort>100</effort>
          <velocity>100</velocity>
          <lower>-1e+16</lower>
          <upper>1e+16</upper>
        </limit>
        <dynamics>
          <damping>0.05</damping>
          <friction>0.05</friction>
          <spring_reference>0</spring_reference>
          <spring_stiffness>0</spring_stiffness>
        </dynamics>
      </axis>
    </joint>
    <link name='wamv/front_left_propeller_link'>
      <pose relative_to='wamv/front_left_engine_propeller_joint'>0 0 0 0 -0 0</pose>
      <inertial>
        <pose>0 0 0 0 -0 0</pose>
        <mass>0.5</mass>
        <inertia>
          <ixx>0.008545</ixx>
          <ixy>0</ixy>
          <ixz>0</ixz>
          <iyy>0.008545</iyy>
          <iyz>0</iyz>
          <izz>0.0144</izz>
        </inertia>
      </inertial>
      <collision name='wamv/front_left_propeller_link_fixed_joint_lump__front_left_propeller_collision_collision'>
        <pose>-0.08 0 0 0 1.5708 0</pose>
        <geometry>
          <cylinder>
            <length>0.18</length>
            <radius>0.24</radius>
          </cylinder>
        </geometry>
      </collision>
      <visual name='wamv/front_left_propeller_link_visual'>
        <pose>0 0 0 0 -0 0</pose>
        <geometry>
          <mesh>
            <scale>1 1 1</scale>
            <uri>model://wamv_description/models/propeller/mesh/propeller.dae</uri>
          </mesh>
        </geometry>
      </visual>
    </link>
    <joint name='wamv/front_right_chasis_engine_joint' type='revolute'>
      <pose relative_to='wamv/base_link'>1.75 -1.02713 0.318237 0 -0 1.5708</pose>
      <parent>wamv/base_link</parent>
      <child>wamv/front_right_engine_link</child>
      <axis>
        <xyz>0 0 1</xyz>
        <limit>
          <lower>-3.14159</lower>
          <upper>3.14159</upper>
          <effort>10</effort>
          <velocity>10</velocity>
        </limit>
        <dynamics>
          <spring_reference>0</spring_reference>
          <spring_stiffness>0</spring_stiffness>
        </dynamics>
      </axis>
    </joint>
    <link name='wamv/front_right_engine_link'>
      <pose relative_to='wamv/front_right_chasis_engine_joint'>0 0 0 0 -0 0</pose>
      <inertial>
        <pose>0 0 0 0 -0 0</pose>
        <mass>15</mass>
        <inertia>
          <ixx>0.889245</ixx>
          <ixy>0</ixy>
          <ixz>0</ixz>
          <iyy>0.911125</iyy>
          <iyz>0</iyz>
          <izz>0.078125</izz>
        </inertia>
      </inertial>
      <collision name='wamv/front_right_engine_link_fixed_joint_lump__front_right_engine_vertical_axis_collision_collision'>
        <pose>-0.16 0 -0.24 0 -0 0</pose>
        <geometry>
          <box>
            <size>0.2 0.15 0.83</size>
          </box>
        </geometry>
      </collision>
      <collision name='wamv/front_right_engine_link_fixed_joint_lump__front_right_engine_rear_end_collision_collision_1'>
        <pose>-0.34 0 0.12 0 -0 0</pose>
        <geometry>
          <box>
            <size>0.12 0.15 0.12</size>
          </box>
        </geometry>
      </collision>
      <visual name='wamv/front_right_engine_link_visual'>
        <pose>0 0 0 0 -0 0</pose>
        <geometry>
          <mesh>
            <scale>1 1 1</scale>
            <uri>model://wamv_description/models/engine/mesh/engine.dae</uri>
          </mesh>
        </geometry>
      </visual>
    </link>
    <joint name='wamv/front_right_engine_propeller_joint' type='revolute'>
      <pose relative_to='wamv/front_right_engine_link'>-0.278156 0 -0.509371 0 -0 0</pose>
      <parent>wamv/front_right_engine_link</parent>
      <child>wamv/front_right_propeller_link</child>
      <axis>
        <xyz>1 0 0</xyz>
        <limit>
          <effort>100</effort>
          <velocity>100</velocity>
          <lower>-1e+16</lower>
          <upper>1e+16</upper>
        </limit>
        <dynamics>
          <damping>0.05</damping>
          <friction>0.05</friction>
          <spring_reference>0</spring_reference>
          <spring_stiffness>0</spring_stiffness>
        </dynamics>
      </axis>
    </joint>
    <link name='wamv/front_right_propeller_link'>
      <pose relative_to='wamv/front_right_engine_propeller_joint'>0 0 0 0 -0 0</pose>
      <inertial>
        <pose>0 0 0 0 -0 0</pose>
        <mass>0.5</mass>
        <inertia>
          <ixx>0.008545</ixx>
          <ixy>0</ixy>
          <ixz>0</ixz>
          <iyy>0.008545</iyy>
          <iyz>0</iyz>
          <izz>0.0144</izz>
        </inertia>
      </inertial>
      <collision name='wamv/front_right_propeller_link_fixed_joint_lump__front_right_propeller_collision_collision'>
        <pose>-0.08 0 0 0 1.5708 0</pose>
        <geometry>
          <cylinder>
            <length>0.18</length>
            <radius>0.24</radius>
          </cylinder>
        </geometry>
      </collision>
      <visual name='wamv/front_right_propeller_link_visual'>
        <pose>0 0 0 0 -0 0</pose>
        <geometry>
          <mesh>
            <scale>1 1 1</scale>
            <uri>model://wamv_description/models/propeller/mesh/propeller.dae</uri>
          </mesh>
        </geometry>
      </visual>
    </link>
    <joint name='wamv/gps_wamv_joint' type='revolute'>
      <pose relative_to='wamv/base_link'>-0.85 0 1.3 0 -0 0</pose>
      <parent>wamv/base_link</parent>
      <child>wamv/gps_wamv_link</child>
      <axis>
        <xyz>0 0 1</xyz>
        <limit>
          <lower>0</lower>
          <upper>0</upper>
          <effort>1000</effort>
          <velocity>0</velocity>
        </limit>
        <dynamics>
          <spring_reference>0</spring_reference>
          <spring_stiffness>0</spring_stiffness>
        </dynamics>
      </axis>
    </joint>
    <link name='wamv/gps_wamv_link'>
      <pose relative_to='wamv/gps_wamv_joint'>0 0 0 0 -0 0</pose>
      <inertial>
        <pose>0 0 0 0 -0 0</pose>
        <mass>1</mass>
        <inertia>
          <ixx>0.006458</ixx>
          <ixy>0</ixy>
          <ixz>0</ixz>
          <iyy>0.006458</iyy>
          <iyz>0</iyz>
          <izz>0.01125</izz>
        </inertia>
      </inertial>
      <collision name='wamv/gps_wamv_link_fixed_joint_lump__gps_wamv_collision_base_collision'>
        <pose>0 0 0.025 0 -0 0</pose>
        <geometry>
          <cylinder>
            <length>0.05</length>
            <radius>0.015</radius>
          </cylinder>
        </geometry>
      </collision>
      <collision name='wamv/gps_wamv_link_fixed_joint_lump__gps_wamv_collision_antenna_collision_1'>
        <pose>0 0 0.11 0 -0 0</pose>
        <geometry>
          <cylinder>
            <length>0.1</length>
            <radius>0.15</radius>
          </cylinder>
        </geometry>
      </collision>
      <visual name='wamv/gps_wamv_link_fixed_joint_lump__gps_wamv_visual_visual'>
        <pose>0 0 0 0 -0 0</pose>
        <geometry>
          <mesh>
            <scale>1 1 1</scale>
            <uri>model://wamv_gazebo/models/gps/mesh/gps.dae</uri>
          </mesh>
        </geometry>
      </visual>
    </link>
    <joint name='wamv/imu_wamv_joint' type='revolute'>
      <pose relative_to='wamv/base_link'>0.3 -0.2 1.3 0 -0 0</pose>
      <parent>wamv/base_link</parent>
      <child>wamv/imu_wamv_link</child>
      <axis>
        <xyz>0 0 1</xyz>
        <limit>
          <lower>0</lower>
          <upper>0</upper>
          <effort>1000</effort>
          <velocity>0</velocity>
        </limit>
        <dynamics>
          <spring_reference>0</spring_reference>
          <spring_stiffness>0</spring_stiffness>
        </dynamics>
      </axis>
    </joint>
    <link name='wamv/imu_wamv_link'>
      <pose relative_to='wamv/imu_wamv_joint'>0 0 0 0 -0 0</pose>
      <inertial>
        <pose>0 0 0 0 -0 0</pose>
        <mass>0.1</mass>
        <inertia>
          <ixx>8.3e-05</ixx>
          <ixy>0</ixy>
          <ixz>0</ixz>
          <iyy>8.3e-05</iyy>
          <iyz>0</iyz>
          <izz>0.0125</izz>
        </inertia>
      </inertial>
      <visual name='wamv/imu_wamv_link_fixed_joint_lump__imu_wamv_visual_visual'>
        <pose>0 0 0 0 -0 0</pose>
        <geometry>
          <box>
            <size>0.05 0.025 0.005</size>
          </box>
        </geometry>
      </visual>
    </link>
    <joint name='wamv/rear_left_chasis_engine_joint' type='revolute'>
      <pose relative_to='wamv/base_link'>-2.37378 1.02713 0.318237 0 -0 0</pose>
      <parent>wamv/base_link</parent>
      <child>wamv/rear_left_engine_link</child>
      <axis>
        <xyz>0 0 1</xyz>
        <limit>
          <lower>-3.14159</lower>
          <upper>3.14159</upper>
          <effort>10</effort>
          <velocity>10</velocity>
        </limit>
        <dynamics>
          <spring_reference>0</spring_reference>
          <spring_stiffness>0</spring_stiffness>
        </dynamics>
      </axis>
    </joint>
    <link name='wamv/rear_left_engine_link'>
      <pose relative_to='wamv/rear_left_chasis_engine_joint'>0 0 0 0 -0 0</pose>
      <inertial>
        <pose>0 0 0 0 -0 0</pose>
        <mass>15</mass>
        <inertia>
          <ixx>0.889245</ixx>
          <ixy>0</ixy>
          <ixz>0</ixz>
          <iyy>0.911125</iyy>
          <iyz>0</iyz>
          <izz>0.078125</izz>
        </inertia>
      </inertial>
      <collision name='wamv/rear_left_engine_link_fixed_joint_lump__rear_left_engine_vertical_axis_collision_collision'>
        <pose>-0.16 0 -0.24 0 -0 0</pose>
        <geometry>
          <box>
            <size>0.2 0.15 0.83</size>
          </box>
        </geometry>
      </collision>
      <collision name='wamv/rear_left_engine_link_fixed_joint_lump__rear_left_engine_rear_end_collision_collision_1'>
        <pose>-0.34 0 0.12 0 -0 0</pose>
        <geometry>
          <box>
            <size>0.12 0.15 0.12</size>
          </box>
        </geometry>
      </collision>
      <visual name='wamv/rear_left_engine_link_visual'>
        <pose>0 0 0 0 -0 0</pose>
        <geometry>
          <mesh>
            <scale>1 1 1</scale>
            <uri>model://wamv_description/models/engine/mesh/engine.dae</uri>
          </mesh>
        </geometry>
      </visual>
    </link>
    <joint name='wamv/rear_left_engine_propeller_joint' type='revolute'>
      <pose relative_to='wamv/rear_left_engine_link'>-0.278156 0 -0.509371 0 -0 0</pose>
      <parent>wamv/rear_left_engine_link</parent>
      <child>wamv/rear_left_propeller_link</child>
      <axis>
        <xyz>1 0 0</xyz>
        <limit>
          <effort>100</effort>
          <velocity>100</velocity>
          <lower>-1e+16</lower>
          <upper>1e+16</upper>
        </limit>
        <dynamics>
          <damping>0.05</damping>
          <friction>0.05</friction>
          <spring_reference>0</spring_reference>
          <spring_stiffness>0</spring_stiffness>
        </dynamics>
      </axis>
    </joint>
    <link name='wamv/rear_left_propeller_link'>
      <pose relative_to='wamv/rear_left_engine_propeller_joint'>0 0 0 0 -0 0</pose>
      <inertial>
        <pose>0 0 0 0 -0 0</pose>
        <mass>0.5</mass>
        <inertia>
          <ixx>0.008545</ixx>
          <ixy>0</ixy>
          <ixz>0</ixz>
          <iyy>0.008545</iyy>
          <iyz>0</iyz>
          <izz>0.0144</izz>
        </inertia>
      </inertial>
      <collision name='wamv/rear_left_propeller_link_fixed_joint_lump__rear_left_propeller_collision_collision'>
        <pose>-0.08 0 0 0 1.5708 0</pose>
        <geometry>
          <cylinder>
            <length>0.18</length>
            <radius>0.24</radius>
          </cylinder>
        </geometry>
      </collision>
      <visual name='wamv/rear_left_propeller_link_visual'>
        <pose>0 0 0 0 -0 0</pose>
        <geometry>
          <mesh>
            <scale>1 1 1</scale>
            <uri>model://wamv_description/models/propeller/mesh/propeller.dae</uri>
          </mesh>
        </geometry>
      </visual>
    </link>
    <joint name='wamv/rear_right_chasis_engine_joint' type='revolute'>
      <pose relative_to='wamv/base_link'>-2.37378 -1.02713 0.318237 0 -0 0</pose>
      <parent>wamv/base_link</parent>
      <child>wamv/rear_right_engine_link</child>
      <axis>
        <xyz>0 0 1</xyz>
        <limit>
          <lower>-3.14159</lower>
          <upper>3.14159</upper>
          <effort>10</effort>
          <velocity>10</velocity>
        </limit>
        <dynamics>
          <spring_reference>0</spring_reference>
          <spring_stiffness>0</spring_stiffness>
        </dynamics>
      </axis>
    </joint>
    <link name='wamv/rear_right_engine_link'>
      <pose relative_to='wamv/rear_right_chasis_engine_joint'>0 0 0 0 -0 0</pose>
      <inertial>
        <pose>0 0 0 0 -0 0</pose>
        <mass>15</mass>
        <inertia>
          <ixx>0.889245</ixx>
          <ixy>0</ixy>
          <ixz>0</ixz>
          <iyy>0.911125</iyy>
          <iyz>0</iyz>
          <izz>0.078125</izz>
        </inertia>
      </inertial>
      <collision name='wamv/rear_right_engine_link_fixed_joint_lump__rear_right_engine_vertical_axis_collision_collision'>
        <pose>-0.16 0 -0.24 0 -0 0</pose>
        <geometry>
          <box>
            <size>0.2 0.15 0.83</size>
          </box>
        </geometry>
      </collision>
      <collision name='wamv/rear_right_engine_link_fixed_joint_lump__rear_right_engine_rear_end_collision_collision_1'>
        <pose>-0.34 0 0.12 0 -0 0</pose>
        <geometry>
          <box>
            <size>0.12 0.15 0.12</size>
          </box>
        </geometry>
      </collision>
      <visual name='wamv/rear_right_engine_link_visual'>
        <pose>0 0 0 0 -0 0</pose>
        <geometry>
          <mesh>
            <scale>1 1 1</scale>
            <uri>model://wamv_description/models/engine/mesh/engine.dae</uri>
          </mesh>
        </geometry>
      </visual>
    </link>
    <joint name='wamv/rear_right_engine_propeller_joint' type='revolute'>
      <pose relative_to='wamv/rear_right_engine_link'>-0.278156 0 -0.509371 0 -0 0</pose>
      <parent>wamv/rear_right_engine_link</parent>
      <child>wamv/rear_right_propeller_link</child>
      <axis>
        <xyz>1 0 0</xyz>
        <limit>
          <effort>100</effort>
          <velocity>100</velocity>
          <lower>-1e+16</lower>
          <upper>1e+16</upper>
        </limit>
        <dynamics>
          <damping>0.05</damping>
          <friction>0.05</friction>
          <spring_reference>0</spring_reference>
          <spring_stiffness>0</spring_stiffness>
        </dynamics>
      </axis>
    </joint>
    <link name='wamv/rear_right_propeller_link'>
      <pose relative_to='wamv/rear_right_engine_propeller_joint'>0 0 0 0 -0 0</pose>
      <inertial>
        <pose>0 0 0 0 -0 0</pose>
        <mass>0.5</mass>
        <inertia>
          <ixx>0.008545</ixx>
          <ixy>0</ixy>
          <ixz>0</ixz>
          <iyy>0.008545</iyy>
          <iyz>0</iyz>
          <izz>0.0144</izz>
        </inertia>
      </inertial>
      <collision name='wamv/rear_right_propeller_link_fixed_joint_lump__rear_right_propeller_collision_collision'>
        <pose>-0.08 0 0 0 1.5708 0</pose>
        <geometry>
          <cylinder>
            <length>0.18</length>
            <radius>0.24</radius>
          </cylinder>
        </geometry>
      </collision>
      <visual name='wamv/rear_right_propeller_link_visual'>
        <pose>0 0 0 0 -0 0</pose>
        <geometry>
          <mesh>
            <scale>1 1 1</scale>
            <uri>model://wamv_description/models/propeller/mesh/propeller.dae</uri>
          </mesh>
        </geometry>
      </visual>
    </link>
    <plugin name='wamv_gazebo_thrust' filename='libusv_gazebo_thrust_plugin.so'>
      <cmdTimeout>1.0</cmdTimeout>
      <robotNamespace>wamv</robotNamespace>
      <thruster>
        <linkName>wamv/rear_left_propeller_link</linkName>
        <propJointName>wamv/rear_left_engine_propeller_joint</propJointName>
        <engineJointName>wamv/rear_left_chasis_engine_joint</engineJointName>
        <cmdTopic>thrusters/rear_left_thrust_cmd</cmdTopic>
        <angleTopic>thrusters/rear_left_thrust_angle</angleTopic>
        <enableAngle>1</enableAngle>
        <mappingType>0</mappingType>
        <maxCmd>1.0</maxCmd>
        <maxForceFwd>200.0</maxForceFwd>
        <maxForceRev>-200.0</maxForceRev>
        <maxAngle>3.141592653589793</maxAngle>
      </thruster>
      <thruster>
        <linkName>wamv/rear_right_propeller_link</linkName>
        <propJointName>wamv/rear_right_engine_propeller_joint</propJointName>
        <engineJointName>wamv/rear_right_chasis_engine_joint</engineJointName>
        <cmdTopic>thrusters/rear_right_thrust_cmd</cmdTopic>
        <angleTopic>thrusters/rear_right_thrust_angle</angleTopic>
        <enableAngle>1</enableAngle>
        <mappingType>0</mappingType>
        <maxCmd>1.0</maxCmd>
        <maxForceFwd>200.0</maxForceFwd>
        <maxForceRev>-200.0</maxForceRev>
        <maxAngle>3.141592653589793</maxAngle>
      </thruster>
      <thruster>
        <linkName>wamv/front_left_propeller_link</linkName>
        <propJointName>wamv/front_left_engine_propeller_joint</propJointName>
        <engineJointName>wamv/front_left_chasis_engine_joint</engineJointName>
        <cmdTopic>thrusters/front_left_thrust_cmd</cmdTopic>
        <angleTopic>thrusters/front_left_thrust_angle</angleTopic>
        <enableAngle>1</enableAngle>
        <mappingType>0</mappingType>
        <maxCmd>1.0</maxCmd>
        <maxForceFwd>200.0</maxForceFwd>
        <maxForceRev>-200.0</maxForceRev>
        <maxAngle>3.141592653589793</maxAngle>
      </thruster>
      <thruster>
        <linkName>wamv/front_right_propeller_link</linkName>
        <propJointName>wamv/front_right_engine_propeller_joint</propJointName>
        <engineJointName>wamv/front_right_chasis_engine_joint</engineJointName>
        <cmdTopic>thrusters/front_right_thrust_cmd</cmdTopic>
        <angleTopic>thrusters/front_right_thrust_angle</angleTopic>
        <enableAngle>1</enableAngle>
        <mappingType>0</mappingType>
        <maxCmd>1.0</maxCmd>
        <maxForceFwd>200.0</maxForceFwd>
        <maxForceRev>-200.0</maxForceRev>
        <maxAngle>3.141592653589793</maxAngle>
      </thruster>
    </plugin>
    <plugin name='usv_dynamics_wamv_dynamics_plugin' filename='libusv_gazebo_dynamics_plugin.so'>
      <bodyName>wamv/base_link</bodyName>
      <waterLevel>0</waterLevel>
      <waterDensity>997.8</waterDensity>
      <xDotU>0.0</xDotU>
      <yDotV>0.0</yDotV>
      <nDotR>0.0</nDotR>
      <xU>35</xU>
      <xUU>40</xUU>
      <yV>850.0</yV>
      <yVV>0.0</yVV>
      <zW>500.0</zW>
      <kP>50.0</kP>
      <mQ>50.0</mQ>
      <nR>1600.0</nR>
      <nRR>0.0</nRR>
      <hullRadius>0.213</hullRadius>
      <boatWidth>2.4</boatWidth>
      <boatLength>4.9</boatLength>
      <length_n>2</length_n>
      <wave_model>ocean_waves</wave_model>
    </plugin>
    <plugin name='gps_plugin_gps_wamv' filename='libhector_gazebo_ros_gps.so'>
      <updateRate>50</updateRate>
      <alwaysOn>1</alwaysOn>
      <bodyName>wamv/gps_wamv_link</bodyName>
      <frameId>wamv/gps_wamv_link</frameId>
      <topicName>wamv/sensors/gps/gps/fix</topicName>
      <velocityTopicName>wamv/sensors/gps/gps/fix_velocity</velocityTopicName>
      <useWorldSphericalCoordinates>1</useWorldSphericalCoordinates>
      <offset>0.0 0.0 0.0</offset>
      <drift>0.0 0.0 0.0</drift>
      <gaussianNoise>0 0 0</gaussianNoise>
      <velocityOffset>0.0 0.0 0.0</velocityOffset>
      <velocityDrift>0.0 0.0 0.0</velocityDrift>
      <velocityGaussianNoise>0.0 0.0 0.0</velocityGaussianNoise>
    </plugin>
    <plugin name='imu_plugin_imu_wamv' filename='libhector_gazebo_ros_imu.so'>
      <updateRate>50</updateRate>
      <bodyName>wamv/imu_wamv_link</bodyName>
      <topicName>wamv/sensors/imu/imu/data</topicName>
      <serviceName>wamv/sensors/imu_service</serviceName>
      <frameId>wamv/imu_wamv_link</frameId>
      <alwaysOn>1</alwaysOn>
      <accelOffset>0.0 0.0 0.0</accelOffset>
      <accelDrift>0.0 0.0 0.0</accelDrift>
      <accelDriftFrequency>0.00027 0.00027 0.000027</accelDriftFrequency>
      <accelGaussianNoise>0.0 0.0 0.0</accelGaussianNoise>
      <rateOffset>0.0 0.0 0.0</rateOffset>
      <rateDrift>0.0 0.0 0.0</rateDrift>
      <rateDriftFrequency>0.00027 0.00027 0.000027</rateDriftFrequency>
      <rateGaussianNoise>0.0 0.0 0.0</rateGaussianNoise>
      <yawOffset>0.0</yawOffset>
      <yawDrift>0.0</yawDrift>
      <yawDriftFrequency>0.00027</yawDriftFrequency>
      <yawGaussianNoise>0.0</yawGaussianNoise>
    </plugin>
    <frame name='wamv/front_camera_to_front_camera_link_optical_joint' attached_to='wamv/front_camera_link'>
      <pose>0 0 0 -1.5708 -0 -1.5708</pose>
    </frame>
    <frame name='wamv/front_camera_link_optical' attached_to='wamv/front_camera_to_front_camera_link_optical_joint'/>
    <frame name='wamv/front_camera_post_arm_to_front_camera_joint' attached_to='wamv/front_camera_post_arm_link'>
      <pose>0.02 0 0.027 0 0.261799 0</pose>
    </frame>
    <frame name='wamv/front_camera_link' attached_to='wamv/front_camera_post_arm_to_front_camera_joint'/>
    <frame name='wamv/front_camera_post_to_front_camera_post_arm_joint' attached_to='wamv/front_camera_post_link'>
      <pose>0.03 0 0.26325 0 -0 0</pose>
    </frame>
    <frame name='wamv/front_camera_post_arm_link' attached_to='wamv/front_camera_post_to_front_camera_post_arm_joint'/>
    <frame name='wamv/base_to_front_camera_post_joint' attached_to='wamv/base_link'>
      <pose>0.7 0 1.55975 0 -0 0</pose>
    </frame>
    <frame name='wamv/front_camera_post_link' attached_to='wamv/base_to_front_camera_post_joint'/>
    <frame name='wamv/lidar_wamv_post_arm_to_lidar_wamv_joint' attached_to='wamv/lidar_wamv_post_arm_link'>
      <pose>0.04 0 0.05 0 0.139626 0</pose>
    </frame>
    <frame name='wamv/lidar_wamv_link' attached_to='wamv/lidar_wamv_post_arm_to_lidar_wamv_joint'/>
    <frame name='wamv/lidar_wamv_post_to_lidar_wamv_post_arm_joint' attached_to='wamv/lidar_wamv_post_link'>
      <pose>0.03 0 0.22675 0 -0 0</pose>
    </frame>
    <frame name='wamv/lidar_wamv_post_arm_link' attached_to='wamv/lidar_wamv_post_to_lidar_wamv_post_arm_joint'/>
    <frame name='wamv/base_to_lidar_wamv_post_joint' attached_to='wamv/base_link'>
      <pose>0.63 0 1.52325 0 -0 0</pose>
    </frame>
    <frame name='wamv/lidar_wamv_post_link' attached_to='wamv/base_to_lidar_wamv_post_joint'/>
    <frame name='wamv/chasis_cpu_cases_joint' attached_to='wamv/base_link'>
      <pose>-0.15 0 1.53 0 -0 0</pose>
    </frame>
    <frame name='wamv/cpu_cases_link' attached_to='wamv/chasis_cpu_cases_joint'/>
    <frame name='wamv/dummy_joint' attached_to='wamv/base_link'>
      <pose>0 0 0 0 -0 0</pose>
    </frame>
    <frame name='wamv/dummy_link' attached_to='wamv/dummy_joint'/>
    <frame name='wamv/left_chasis_battery_joint' attached_to='wamv/base_link'>
      <pose>0 1 0.45 0 -0 0</pose>
    </frame>
    <frame name='wamv/left_battery_link' attached_to='wamv/left_chasis_battery_joint'/>
    <frame name='wamv/right_chasis_battery_joint' attached_to='wamv/base_link'>
      <pose>0 -1 0.45 0 -0 0</pose>
    </frame>
    <frame name='wamv/right_battery_link' attached_to='wamv/right_chasis_battery_joint'/>
  </model>
</sdf>